<?xml version="1.0"?>
<robot name="gpg3" xmlns:xacro="http://www.ros.org/wiki/xacro">

  <material name="blue">
    <color rgba="0 0 .8 1"/>
  </material>

  <material name="white">
    <color rgba="1 1 1 1"/>
  </material>

  <!-- 'base_footprint' is the ground link -->
  <link name="base_footprint"/>

  <joint name="base_joint" type="fixed">
    <parent link="base_footprint"/>
    <child link="base_link"/>
    <origin xyz="0 0 0.05" rpy="0 0 0"/>
  </joint>

  <link name="base_link">
    <visual>
      <geometry>
        <box size="0.18 0.10 0.05"/>
      </geometry>
      <material name="white"/>
    </visual>
    <collision>
      <geometry>
        <box size="0.18 0.10 0.05"/>
      </geometry>
	</collision>
    <inertial>
      <origin xyz="-0.02 0 0" rpy="0 0 0"/>
      <mass value="0.534"/>
      <inertia ixx="1.0e-03" ixy="0" ixz="0" iyy="1.0e-03" iyz="0" izz="2.45e-03" />
    </inertial>
  </link>

  <link name="left_wheel_link">
    <visual>
      <origin rpy="1.57075 0 0"/>
      <geometry>
        <cylinder length="0.02" radius="0.03"/>
      </geometry>
      <material name="blue"/>
    </visual>
    <collision>
      <origin rpy="1.57075 0 0"/>
      <geometry>
        <cylinder length="0.02" radius="0.03"/>
      </geometry>
	</collision>
    <inertial>
      <mass value="0.032" />
      <inertia ixx="1.74e-05" ixy="0" ixz="0" iyy="1.05e-05" iyz="0" izz="1.05e-05" />
    </inertial>
  </link>

  <joint name="left_wheel" type="continuous">
    <parent link="base_link"/>
    <child link="left_wheel_link"/>
    <origin xyz="0 0.06 -0.025"/>
    <axis xyz="0 1 0"/>
  </joint>

  <link name="right_wheel_link">
    <visual>
      <origin rpy="1.57075 0 0"/>
      <geometry>
        <cylinder length="0.02" radius="0.03"/>
      </geometry>
      <material name="blue"/>
    </visual>
    <collision>
      <origin rpy="1.57075 0 0"/>
      <geometry>
        <cylinder length="0.02" radius="0.03"/>
      </geometry>
      <material name="blue"/>
    </collision>
    <inertial>
      <origin xyz="0 0 0" />
      <mass value="0.032" />
      <inertia ixx="1.74e-05" ixy="0" ixz="0" iyy="1.05e-05" iyz="0" izz="1.05e-05" />
    </inertial>
  </link>

  <joint name="right_wheel" type="continuous">
    <parent link="base_link"/>
    <child link="right_wheel_link"/>
    <origin xyz="0 -0.06 -0.025"/>
    <axis xyz="0 1 0"/>
  </joint>

  <link name="camera_link">
    <visual>
      <geometry>
        <box size="0.03 0.03 0.01"/>
      </geometry>
    </visual>
    <collision>
      <geometry>
        <box size="0.03 0.03 0.01"/>
      </geometry>
    </collision>
	<inertial>
	  <mass value="0.178" />
	  <inertia ixx="1.10e-04" ixy="-1.56e-04" ixz="-3.12e-04" iyy="1.85e-04" iyz="-2.23e-04" izz="2.21e-04" />
	</inertial>
  </link>

  <joint name="servo" type="revolute">
    <axis xyz="0 -1 0"/>
    <limit effort="1000.0" lower="-1" upper="1" velocity="0.5"/>
    <parent link="base_link"/>
    <child link="camera_link"/>
    <origin rpy="-1.57075 0 -1.57075" xyz="0.11 0 0.025"/>
  </joint>

  <!-- Gazebo plugin for ROS Control -->
  <gazebo>
    <plugin name="gazebo_ros_control" filename="libgazebo_ros_control.so">
      <robotNamespace>/</robotNamespace>
    </plugin>
  </gazebo>

</robot>
