<?xml version="1.0"?>
<robot name="gpg3">

  <material name="blue">
    <color rgba="0 0 .8 1"/>
  </material>

  <material name="white">
    <color rgba="1 1 1 1"/>
  </material>

  <link name="base_link">
    <visual>
      <geometry>
        <box size="0.18 0.10 0.05"/>
      </geometry>
      <material name="white"/>
    </visual>
  </link>

  <link name="left_wheel_link">
    <visual>
      <origin rpy="1.57075 0 0"/>
      <geometry>
        <cylinder length="0.02" radius="0.03"/>
      </geometry>
      <material name="blue"/>
    </visual>
  </link>

  <joint name="left_wheel" type="continuous">
    <parent link="base_link"/>
    <child link="left_wheel_link"/>
    <origin xyz="0 0.06 -0.025"/>
    <axis xyz="0 1 0"/>
  </joint>

  <link name="right_wheel_link">
    <visual>
      <origin rpy="1.57075 0 0"/>
      <geometry>
        <cylinder length="0.02" radius="0.03"/>
      </geometry>
      <material name="blue"/>
    </visual>
  </link>

  <joint name="right_wheel" type="continuous">
    <parent link="base_link"/>
    <child link="right_wheel_link"/>
    <origin xyz="0 -0.06 -0.025"/>
    <axis xyz="0 1 0"/>
  </joint>

  <link name="camera_link">
    <visual>
      <geometry>
        <box size="0.03 0.03 0.01"/>
      </geometry>
    </visual>
  </link>

  <joint name="servo" type="revolute">
    <axis xyz="0 -1 0"/>
    <limit effort="1000.0" lower="-1" upper="1" velocity="0.5"/>
    <parent link="base_link"/>
    <child link="camera_link"/>
    <origin rpy="-1.57075 0 -1.57075" xyz="0.11 0 0.025"/>
  </joint>

</robot>
